Выдается ошибка
```python
consumer: Cannot connect to redis://redis:6379/3: Error -3 connecting to redis:6379. Lookup timed out..
Trying again in 2.00 seconds... (1/100)
``` 
Шаги:
1. Проверить енвы
2. Проверить докер-композе
3. Проверить что контейнеры находятся в одной сети (inspect, lookup)
4. Проверить команду запуска (7.03.2024 проблема была в том, что было установлено 1000 процессов, вернули настройку с 4 процессами)