Выдается ошибка
```python
consumer: Cannot connect to redis://redis:6379/3: Error -3 connecting to redis:6379. Lookup timed out..
Trying again in 2.00 seconds... (1/100)
``` 
Шаги:
1. Проверить е